{
 "cells": [
  {
   "cell_type": "markdown",
   "metadata": {},
   "source": [
    "# Проверяем что сервис работает"
   ]
  },
  {
   "cell_type": "code",
   "outputs": [],
   "source": [
    "# server_url = \"https://applied-python-hw-project.onrender.com\"\n",
    "server_url = \"http://localhost:5555\""
   ],
   "metadata": {
    "collapsed": false,
    "ExecuteTime": {
     "end_time": "2024-03-20T14:43:00.494014Z",
     "start_time": "2024-03-20T14:43:00.489522Z"
    }
   },
   "execution_count": 1
  },
  {
   "cell_type": "code",
   "execution_count": 3,
   "metadata": {
    "ExecuteTime": {
     "end_time": "2024-03-20T14:43:35.026067Z",
     "start_time": "2024-03-20T14:43:34.932047Z"
    }
   },
   "outputs": [
    {
     "ename": "ConnectionError",
     "evalue": "HTTPConnectionPool(host='localhost', port=5555): Max retries exceeded with url: /ping (Caused by NewConnectionError('<urllib3.connection.HTTPConnection object at 0x1096fb340>: Failed to establish a new connection: [Errno 61] Connection refused'))",
     "output_type": "error",
     "traceback": [
      "\u001B[0;31m---------------------------------------------------------------------------\u001B[0m",
      "\u001B[0;31mConnectionRefusedError\u001B[0m                    Traceback (most recent call last)",
      "File \u001B[0;32m~/Documents/Магистратура/Прикладной питон/applied_python_hw_project/.venv/lib/python3.10/site-packages/urllib3/connection.py:198\u001B[0m, in \u001B[0;36mHTTPConnection._new_conn\u001B[0;34m(self)\u001B[0m\n\u001B[1;32m    197\u001B[0m \u001B[38;5;28;01mtry\u001B[39;00m:\n\u001B[0;32m--> 198\u001B[0m     sock \u001B[38;5;241m=\u001B[39m \u001B[43mconnection\u001B[49m\u001B[38;5;241;43m.\u001B[39;49m\u001B[43mcreate_connection\u001B[49m\u001B[43m(\u001B[49m\n\u001B[1;32m    199\u001B[0m \u001B[43m        \u001B[49m\u001B[43m(\u001B[49m\u001B[38;5;28;43mself\u001B[39;49m\u001B[38;5;241;43m.\u001B[39;49m\u001B[43m_dns_host\u001B[49m\u001B[43m,\u001B[49m\u001B[43m \u001B[49m\u001B[38;5;28;43mself\u001B[39;49m\u001B[38;5;241;43m.\u001B[39;49m\u001B[43mport\u001B[49m\u001B[43m)\u001B[49m\u001B[43m,\u001B[49m\n\u001B[1;32m    200\u001B[0m \u001B[43m        \u001B[49m\u001B[38;5;28;43mself\u001B[39;49m\u001B[38;5;241;43m.\u001B[39;49m\u001B[43mtimeout\u001B[49m\u001B[43m,\u001B[49m\n\u001B[1;32m    201\u001B[0m \u001B[43m        \u001B[49m\u001B[43msource_address\u001B[49m\u001B[38;5;241;43m=\u001B[39;49m\u001B[38;5;28;43mself\u001B[39;49m\u001B[38;5;241;43m.\u001B[39;49m\u001B[43msource_address\u001B[49m\u001B[43m,\u001B[49m\n\u001B[1;32m    202\u001B[0m \u001B[43m        \u001B[49m\u001B[43msocket_options\u001B[49m\u001B[38;5;241;43m=\u001B[39;49m\u001B[38;5;28;43mself\u001B[39;49m\u001B[38;5;241;43m.\u001B[39;49m\u001B[43msocket_options\u001B[49m\u001B[43m,\u001B[49m\n\u001B[1;32m    203\u001B[0m \u001B[43m    \u001B[49m\u001B[43m)\u001B[49m\n\u001B[1;32m    204\u001B[0m \u001B[38;5;28;01mexcept\u001B[39;00m socket\u001B[38;5;241m.\u001B[39mgaierror \u001B[38;5;28;01mas\u001B[39;00m e:\n",
      "File \u001B[0;32m~/Documents/Магистратура/Прикладной питон/applied_python_hw_project/.venv/lib/python3.10/site-packages/urllib3/util/connection.py:85\u001B[0m, in \u001B[0;36mcreate_connection\u001B[0;34m(address, timeout, source_address, socket_options)\u001B[0m\n\u001B[1;32m     84\u001B[0m \u001B[38;5;28;01mtry\u001B[39;00m:\n\u001B[0;32m---> 85\u001B[0m     \u001B[38;5;28;01mraise\u001B[39;00m err\n\u001B[1;32m     86\u001B[0m \u001B[38;5;28;01mfinally\u001B[39;00m:\n\u001B[1;32m     87\u001B[0m     \u001B[38;5;66;03m# Break explicitly a reference cycle\u001B[39;00m\n",
      "File \u001B[0;32m~/Documents/Магистратура/Прикладной питон/applied_python_hw_project/.venv/lib/python3.10/site-packages/urllib3/util/connection.py:73\u001B[0m, in \u001B[0;36mcreate_connection\u001B[0;34m(address, timeout, source_address, socket_options)\u001B[0m\n\u001B[1;32m     72\u001B[0m     sock\u001B[38;5;241m.\u001B[39mbind(source_address)\n\u001B[0;32m---> 73\u001B[0m \u001B[43msock\u001B[49m\u001B[38;5;241;43m.\u001B[39;49m\u001B[43mconnect\u001B[49m\u001B[43m(\u001B[49m\u001B[43msa\u001B[49m\u001B[43m)\u001B[49m\n\u001B[1;32m     74\u001B[0m \u001B[38;5;66;03m# Break explicitly a reference cycle\u001B[39;00m\n",
      "\u001B[0;31mConnectionRefusedError\u001B[0m: [Errno 61] Connection refused",
      "\nThe above exception was the direct cause of the following exception:\n",
      "\u001B[0;31mNewConnectionError\u001B[0m                        Traceback (most recent call last)",
      "File \u001B[0;32m~/Documents/Магистратура/Прикладной питон/applied_python_hw_project/.venv/lib/python3.10/site-packages/urllib3/connectionpool.py:793\u001B[0m, in \u001B[0;36mHTTPConnectionPool.urlopen\u001B[0;34m(self, method, url, body, headers, retries, redirect, assert_same_host, timeout, pool_timeout, release_conn, chunked, body_pos, preload_content, decode_content, **response_kw)\u001B[0m\n\u001B[1;32m    792\u001B[0m \u001B[38;5;66;03m# Make the request on the HTTPConnection object\u001B[39;00m\n\u001B[0;32m--> 793\u001B[0m response \u001B[38;5;241m=\u001B[39m \u001B[38;5;28;43mself\u001B[39;49m\u001B[38;5;241;43m.\u001B[39;49m\u001B[43m_make_request\u001B[49m\u001B[43m(\u001B[49m\n\u001B[1;32m    794\u001B[0m \u001B[43m    \u001B[49m\u001B[43mconn\u001B[49m\u001B[43m,\u001B[49m\n\u001B[1;32m    795\u001B[0m \u001B[43m    \u001B[49m\u001B[43mmethod\u001B[49m\u001B[43m,\u001B[49m\n\u001B[1;32m    796\u001B[0m \u001B[43m    \u001B[49m\u001B[43murl\u001B[49m\u001B[43m,\u001B[49m\n\u001B[1;32m    797\u001B[0m \u001B[43m    \u001B[49m\u001B[43mtimeout\u001B[49m\u001B[38;5;241;43m=\u001B[39;49m\u001B[43mtimeout_obj\u001B[49m\u001B[43m,\u001B[49m\n\u001B[1;32m    798\u001B[0m \u001B[43m    \u001B[49m\u001B[43mbody\u001B[49m\u001B[38;5;241;43m=\u001B[39;49m\u001B[43mbody\u001B[49m\u001B[43m,\u001B[49m\n\u001B[1;32m    799\u001B[0m \u001B[43m    \u001B[49m\u001B[43mheaders\u001B[49m\u001B[38;5;241;43m=\u001B[39;49m\u001B[43mheaders\u001B[49m\u001B[43m,\u001B[49m\n\u001B[1;32m    800\u001B[0m \u001B[43m    \u001B[49m\u001B[43mchunked\u001B[49m\u001B[38;5;241;43m=\u001B[39;49m\u001B[43mchunked\u001B[49m\u001B[43m,\u001B[49m\n\u001B[1;32m    801\u001B[0m \u001B[43m    \u001B[49m\u001B[43mretries\u001B[49m\u001B[38;5;241;43m=\u001B[39;49m\u001B[43mretries\u001B[49m\u001B[43m,\u001B[49m\n\u001B[1;32m    802\u001B[0m \u001B[43m    \u001B[49m\u001B[43mresponse_conn\u001B[49m\u001B[38;5;241;43m=\u001B[39;49m\u001B[43mresponse_conn\u001B[49m\u001B[43m,\u001B[49m\n\u001B[1;32m    803\u001B[0m \u001B[43m    \u001B[49m\u001B[43mpreload_content\u001B[49m\u001B[38;5;241;43m=\u001B[39;49m\u001B[43mpreload_content\u001B[49m\u001B[43m,\u001B[49m\n\u001B[1;32m    804\u001B[0m \u001B[43m    \u001B[49m\u001B[43mdecode_content\u001B[49m\u001B[38;5;241;43m=\u001B[39;49m\u001B[43mdecode_content\u001B[49m\u001B[43m,\u001B[49m\n\u001B[1;32m    805\u001B[0m \u001B[43m    \u001B[49m\u001B[38;5;241;43m*\u001B[39;49m\u001B[38;5;241;43m*\u001B[39;49m\u001B[43mresponse_kw\u001B[49m\u001B[43m,\u001B[49m\n\u001B[1;32m    806\u001B[0m \u001B[43m\u001B[49m\u001B[43m)\u001B[49m\n\u001B[1;32m    808\u001B[0m \u001B[38;5;66;03m# Everything went great!\u001B[39;00m\n",
      "File \u001B[0;32m~/Documents/Магистратура/Прикладной питон/applied_python_hw_project/.venv/lib/python3.10/site-packages/urllib3/connectionpool.py:496\u001B[0m, in \u001B[0;36mHTTPConnectionPool._make_request\u001B[0;34m(self, conn, method, url, body, headers, retries, timeout, chunked, response_conn, preload_content, decode_content, enforce_content_length)\u001B[0m\n\u001B[1;32m    495\u001B[0m \u001B[38;5;28;01mtry\u001B[39;00m:\n\u001B[0;32m--> 496\u001B[0m     \u001B[43mconn\u001B[49m\u001B[38;5;241;43m.\u001B[39;49m\u001B[43mrequest\u001B[49m\u001B[43m(\u001B[49m\n\u001B[1;32m    497\u001B[0m \u001B[43m        \u001B[49m\u001B[43mmethod\u001B[49m\u001B[43m,\u001B[49m\n\u001B[1;32m    498\u001B[0m \u001B[43m        \u001B[49m\u001B[43murl\u001B[49m\u001B[43m,\u001B[49m\n\u001B[1;32m    499\u001B[0m \u001B[43m        \u001B[49m\u001B[43mbody\u001B[49m\u001B[38;5;241;43m=\u001B[39;49m\u001B[43mbody\u001B[49m\u001B[43m,\u001B[49m\n\u001B[1;32m    500\u001B[0m \u001B[43m        \u001B[49m\u001B[43mheaders\u001B[49m\u001B[38;5;241;43m=\u001B[39;49m\u001B[43mheaders\u001B[49m\u001B[43m,\u001B[49m\n\u001B[1;32m    501\u001B[0m \u001B[43m        \u001B[49m\u001B[43mchunked\u001B[49m\u001B[38;5;241;43m=\u001B[39;49m\u001B[43mchunked\u001B[49m\u001B[43m,\u001B[49m\n\u001B[1;32m    502\u001B[0m \u001B[43m        \u001B[49m\u001B[43mpreload_content\u001B[49m\u001B[38;5;241;43m=\u001B[39;49m\u001B[43mpreload_content\u001B[49m\u001B[43m,\u001B[49m\n\u001B[1;32m    503\u001B[0m \u001B[43m        \u001B[49m\u001B[43mdecode_content\u001B[49m\u001B[38;5;241;43m=\u001B[39;49m\u001B[43mdecode_content\u001B[49m\u001B[43m,\u001B[49m\n\u001B[1;32m    504\u001B[0m \u001B[43m        \u001B[49m\u001B[43menforce_content_length\u001B[49m\u001B[38;5;241;43m=\u001B[39;49m\u001B[43menforce_content_length\u001B[49m\u001B[43m,\u001B[49m\n\u001B[1;32m    505\u001B[0m \u001B[43m    \u001B[49m\u001B[43m)\u001B[49m\n\u001B[1;32m    507\u001B[0m \u001B[38;5;66;03m# We are swallowing BrokenPipeError (errno.EPIPE) since the server is\u001B[39;00m\n\u001B[1;32m    508\u001B[0m \u001B[38;5;66;03m# legitimately able to close the connection after sending a valid response.\u001B[39;00m\n\u001B[1;32m    509\u001B[0m \u001B[38;5;66;03m# With this behaviour, the received response is still readable.\u001B[39;00m\n",
      "File \u001B[0;32m~/Documents/Магистратура/Прикладной питон/applied_python_hw_project/.venv/lib/python3.10/site-packages/urllib3/connection.py:400\u001B[0m, in \u001B[0;36mHTTPConnection.request\u001B[0;34m(self, method, url, body, headers, chunked, preload_content, decode_content, enforce_content_length)\u001B[0m\n\u001B[1;32m    399\u001B[0m     \u001B[38;5;28mself\u001B[39m\u001B[38;5;241m.\u001B[39mputheader(header, value)\n\u001B[0;32m--> 400\u001B[0m \u001B[38;5;28;43mself\u001B[39;49m\u001B[38;5;241;43m.\u001B[39;49m\u001B[43mendheaders\u001B[49m\u001B[43m(\u001B[49m\u001B[43m)\u001B[49m\n\u001B[1;32m    402\u001B[0m \u001B[38;5;66;03m# If we're given a body we start sending that in chunks.\u001B[39;00m\n",
      "File \u001B[0;32m/Library/Frameworks/Python.framework/Versions/3.10/lib/python3.10/http/client.py:1278\u001B[0m, in \u001B[0;36mHTTPConnection.endheaders\u001B[0;34m(self, message_body, encode_chunked)\u001B[0m\n\u001B[1;32m   1277\u001B[0m     \u001B[38;5;28;01mraise\u001B[39;00m CannotSendHeader()\n\u001B[0;32m-> 1278\u001B[0m \u001B[38;5;28;43mself\u001B[39;49m\u001B[38;5;241;43m.\u001B[39;49m\u001B[43m_send_output\u001B[49m\u001B[43m(\u001B[49m\u001B[43mmessage_body\u001B[49m\u001B[43m,\u001B[49m\u001B[43m \u001B[49m\u001B[43mencode_chunked\u001B[49m\u001B[38;5;241;43m=\u001B[39;49m\u001B[43mencode_chunked\u001B[49m\u001B[43m)\u001B[49m\n",
      "File \u001B[0;32m/Library/Frameworks/Python.framework/Versions/3.10/lib/python3.10/http/client.py:1038\u001B[0m, in \u001B[0;36mHTTPConnection._send_output\u001B[0;34m(self, message_body, encode_chunked)\u001B[0m\n\u001B[1;32m   1037\u001B[0m \u001B[38;5;28;01mdel\u001B[39;00m \u001B[38;5;28mself\u001B[39m\u001B[38;5;241m.\u001B[39m_buffer[:]\n\u001B[0;32m-> 1038\u001B[0m \u001B[38;5;28;43mself\u001B[39;49m\u001B[38;5;241;43m.\u001B[39;49m\u001B[43msend\u001B[49m\u001B[43m(\u001B[49m\u001B[43mmsg\u001B[49m\u001B[43m)\u001B[49m\n\u001B[1;32m   1040\u001B[0m \u001B[38;5;28;01mif\u001B[39;00m message_body \u001B[38;5;129;01mis\u001B[39;00m \u001B[38;5;129;01mnot\u001B[39;00m \u001B[38;5;28;01mNone\u001B[39;00m:\n\u001B[1;32m   1041\u001B[0m \n\u001B[1;32m   1042\u001B[0m     \u001B[38;5;66;03m# create a consistent interface to message_body\u001B[39;00m\n",
      "File \u001B[0;32m/Library/Frameworks/Python.framework/Versions/3.10/lib/python3.10/http/client.py:976\u001B[0m, in \u001B[0;36mHTTPConnection.send\u001B[0;34m(self, data)\u001B[0m\n\u001B[1;32m    975\u001B[0m \u001B[38;5;28;01mif\u001B[39;00m \u001B[38;5;28mself\u001B[39m\u001B[38;5;241m.\u001B[39mauto_open:\n\u001B[0;32m--> 976\u001B[0m     \u001B[38;5;28;43mself\u001B[39;49m\u001B[38;5;241;43m.\u001B[39;49m\u001B[43mconnect\u001B[49m\u001B[43m(\u001B[49m\u001B[43m)\u001B[49m\n\u001B[1;32m    977\u001B[0m \u001B[38;5;28;01melse\u001B[39;00m:\n",
      "File \u001B[0;32m~/Documents/Магистратура/Прикладной питон/applied_python_hw_project/.venv/lib/python3.10/site-packages/urllib3/connection.py:238\u001B[0m, in \u001B[0;36mHTTPConnection.connect\u001B[0;34m(self)\u001B[0m\n\u001B[1;32m    237\u001B[0m \u001B[38;5;28;01mdef\u001B[39;00m \u001B[38;5;21mconnect\u001B[39m(\u001B[38;5;28mself\u001B[39m) \u001B[38;5;241m-\u001B[39m\u001B[38;5;241m>\u001B[39m \u001B[38;5;28;01mNone\u001B[39;00m:\n\u001B[0;32m--> 238\u001B[0m     \u001B[38;5;28mself\u001B[39m\u001B[38;5;241m.\u001B[39msock \u001B[38;5;241m=\u001B[39m \u001B[38;5;28;43mself\u001B[39;49m\u001B[38;5;241;43m.\u001B[39;49m\u001B[43m_new_conn\u001B[49m\u001B[43m(\u001B[49m\u001B[43m)\u001B[49m\n\u001B[1;32m    239\u001B[0m     \u001B[38;5;28;01mif\u001B[39;00m \u001B[38;5;28mself\u001B[39m\u001B[38;5;241m.\u001B[39m_tunnel_host:\n\u001B[1;32m    240\u001B[0m         \u001B[38;5;66;03m# If we're tunneling it means we're connected to our proxy.\u001B[39;00m\n",
      "File \u001B[0;32m~/Documents/Магистратура/Прикладной питон/applied_python_hw_project/.venv/lib/python3.10/site-packages/urllib3/connection.py:213\u001B[0m, in \u001B[0;36mHTTPConnection._new_conn\u001B[0;34m(self)\u001B[0m\n\u001B[1;32m    212\u001B[0m \u001B[38;5;28;01mexcept\u001B[39;00m \u001B[38;5;167;01mOSError\u001B[39;00m \u001B[38;5;28;01mas\u001B[39;00m e:\n\u001B[0;32m--> 213\u001B[0m     \u001B[38;5;28;01mraise\u001B[39;00m NewConnectionError(\n\u001B[1;32m    214\u001B[0m         \u001B[38;5;28mself\u001B[39m, \u001B[38;5;124mf\u001B[39m\u001B[38;5;124m\"\u001B[39m\u001B[38;5;124mFailed to establish a new connection: \u001B[39m\u001B[38;5;132;01m{\u001B[39;00me\u001B[38;5;132;01m}\u001B[39;00m\u001B[38;5;124m\"\u001B[39m\n\u001B[1;32m    215\u001B[0m     ) \u001B[38;5;28;01mfrom\u001B[39;00m \u001B[38;5;21;01me\u001B[39;00m\n\u001B[1;32m    217\u001B[0m \u001B[38;5;66;03m# Audit hooks are only available in Python 3.8+\u001B[39;00m\n",
      "\u001B[0;31mNewConnectionError\u001B[0m: <urllib3.connection.HTTPConnection object at 0x1096fb340>: Failed to establish a new connection: [Errno 61] Connection refused",
      "\nThe above exception was the direct cause of the following exception:\n",
      "\u001B[0;31mMaxRetryError\u001B[0m                             Traceback (most recent call last)",
      "File \u001B[0;32m~/Documents/Магистратура/Прикладной питон/applied_python_hw_project/.venv/lib/python3.10/site-packages/requests/adapters.py:486\u001B[0m, in \u001B[0;36mHTTPAdapter.send\u001B[0;34m(self, request, stream, timeout, verify, cert, proxies)\u001B[0m\n\u001B[1;32m    485\u001B[0m \u001B[38;5;28;01mtry\u001B[39;00m:\n\u001B[0;32m--> 486\u001B[0m     resp \u001B[38;5;241m=\u001B[39m \u001B[43mconn\u001B[49m\u001B[38;5;241;43m.\u001B[39;49m\u001B[43murlopen\u001B[49m\u001B[43m(\u001B[49m\n\u001B[1;32m    487\u001B[0m \u001B[43m        \u001B[49m\u001B[43mmethod\u001B[49m\u001B[38;5;241;43m=\u001B[39;49m\u001B[43mrequest\u001B[49m\u001B[38;5;241;43m.\u001B[39;49m\u001B[43mmethod\u001B[49m\u001B[43m,\u001B[49m\n\u001B[1;32m    488\u001B[0m \u001B[43m        \u001B[49m\u001B[43murl\u001B[49m\u001B[38;5;241;43m=\u001B[39;49m\u001B[43murl\u001B[49m\u001B[43m,\u001B[49m\n\u001B[1;32m    489\u001B[0m \u001B[43m        \u001B[49m\u001B[43mbody\u001B[49m\u001B[38;5;241;43m=\u001B[39;49m\u001B[43mrequest\u001B[49m\u001B[38;5;241;43m.\u001B[39;49m\u001B[43mbody\u001B[49m\u001B[43m,\u001B[49m\n\u001B[1;32m    490\u001B[0m \u001B[43m        \u001B[49m\u001B[43mheaders\u001B[49m\u001B[38;5;241;43m=\u001B[39;49m\u001B[43mrequest\u001B[49m\u001B[38;5;241;43m.\u001B[39;49m\u001B[43mheaders\u001B[49m\u001B[43m,\u001B[49m\n\u001B[1;32m    491\u001B[0m \u001B[43m        \u001B[49m\u001B[43mredirect\u001B[49m\u001B[38;5;241;43m=\u001B[39;49m\u001B[38;5;28;43;01mFalse\u001B[39;49;00m\u001B[43m,\u001B[49m\n\u001B[1;32m    492\u001B[0m \u001B[43m        \u001B[49m\u001B[43massert_same_host\u001B[49m\u001B[38;5;241;43m=\u001B[39;49m\u001B[38;5;28;43;01mFalse\u001B[39;49;00m\u001B[43m,\u001B[49m\n\u001B[1;32m    493\u001B[0m \u001B[43m        \u001B[49m\u001B[43mpreload_content\u001B[49m\u001B[38;5;241;43m=\u001B[39;49m\u001B[38;5;28;43;01mFalse\u001B[39;49;00m\u001B[43m,\u001B[49m\n\u001B[1;32m    494\u001B[0m \u001B[43m        \u001B[49m\u001B[43mdecode_content\u001B[49m\u001B[38;5;241;43m=\u001B[39;49m\u001B[38;5;28;43;01mFalse\u001B[39;49;00m\u001B[43m,\u001B[49m\n\u001B[1;32m    495\u001B[0m \u001B[43m        \u001B[49m\u001B[43mretries\u001B[49m\u001B[38;5;241;43m=\u001B[39;49m\u001B[38;5;28;43mself\u001B[39;49m\u001B[38;5;241;43m.\u001B[39;49m\u001B[43mmax_retries\u001B[49m\u001B[43m,\u001B[49m\n\u001B[1;32m    496\u001B[0m \u001B[43m        \u001B[49m\u001B[43mtimeout\u001B[49m\u001B[38;5;241;43m=\u001B[39;49m\u001B[43mtimeout\u001B[49m\u001B[43m,\u001B[49m\n\u001B[1;32m    497\u001B[0m \u001B[43m        \u001B[49m\u001B[43mchunked\u001B[49m\u001B[38;5;241;43m=\u001B[39;49m\u001B[43mchunked\u001B[49m\u001B[43m,\u001B[49m\n\u001B[1;32m    498\u001B[0m \u001B[43m    \u001B[49m\u001B[43m)\u001B[49m\n\u001B[1;32m    500\u001B[0m \u001B[38;5;28;01mexcept\u001B[39;00m (ProtocolError, \u001B[38;5;167;01mOSError\u001B[39;00m) \u001B[38;5;28;01mas\u001B[39;00m err:\n",
      "File \u001B[0;32m~/Documents/Магистратура/Прикладной питон/applied_python_hw_project/.venv/lib/python3.10/site-packages/urllib3/connectionpool.py:847\u001B[0m, in \u001B[0;36mHTTPConnectionPool.urlopen\u001B[0;34m(self, method, url, body, headers, retries, redirect, assert_same_host, timeout, pool_timeout, release_conn, chunked, body_pos, preload_content, decode_content, **response_kw)\u001B[0m\n\u001B[1;32m    845\u001B[0m     new_e \u001B[38;5;241m=\u001B[39m ProtocolError(\u001B[38;5;124m\"\u001B[39m\u001B[38;5;124mConnection aborted.\u001B[39m\u001B[38;5;124m\"\u001B[39m, new_e)\n\u001B[0;32m--> 847\u001B[0m retries \u001B[38;5;241m=\u001B[39m \u001B[43mretries\u001B[49m\u001B[38;5;241;43m.\u001B[39;49m\u001B[43mincrement\u001B[49m\u001B[43m(\u001B[49m\n\u001B[1;32m    848\u001B[0m \u001B[43m    \u001B[49m\u001B[43mmethod\u001B[49m\u001B[43m,\u001B[49m\u001B[43m \u001B[49m\u001B[43murl\u001B[49m\u001B[43m,\u001B[49m\u001B[43m \u001B[49m\u001B[43merror\u001B[49m\u001B[38;5;241;43m=\u001B[39;49m\u001B[43mnew_e\u001B[49m\u001B[43m,\u001B[49m\u001B[43m \u001B[49m\u001B[43m_pool\u001B[49m\u001B[38;5;241;43m=\u001B[39;49m\u001B[38;5;28;43mself\u001B[39;49m\u001B[43m,\u001B[49m\u001B[43m \u001B[49m\u001B[43m_stacktrace\u001B[49m\u001B[38;5;241;43m=\u001B[39;49m\u001B[43msys\u001B[49m\u001B[38;5;241;43m.\u001B[39;49m\u001B[43mexc_info\u001B[49m\u001B[43m(\u001B[49m\u001B[43m)\u001B[49m\u001B[43m[\u001B[49m\u001B[38;5;241;43m2\u001B[39;49m\u001B[43m]\u001B[49m\n\u001B[1;32m    849\u001B[0m \u001B[43m\u001B[49m\u001B[43m)\u001B[49m\n\u001B[1;32m    850\u001B[0m retries\u001B[38;5;241m.\u001B[39msleep()\n",
      "File \u001B[0;32m~/Documents/Магистратура/Прикладной питон/applied_python_hw_project/.venv/lib/python3.10/site-packages/urllib3/util/retry.py:515\u001B[0m, in \u001B[0;36mRetry.increment\u001B[0;34m(self, method, url, response, error, _pool, _stacktrace)\u001B[0m\n\u001B[1;32m    514\u001B[0m     reason \u001B[38;5;241m=\u001B[39m error \u001B[38;5;129;01mor\u001B[39;00m ResponseError(cause)\n\u001B[0;32m--> 515\u001B[0m     \u001B[38;5;28;01mraise\u001B[39;00m MaxRetryError(_pool, url, reason) \u001B[38;5;28;01mfrom\u001B[39;00m \u001B[38;5;21;01mreason\u001B[39;00m  \u001B[38;5;66;03m# type: ignore[arg-type]\u001B[39;00m\n\u001B[1;32m    517\u001B[0m log\u001B[38;5;241m.\u001B[39mdebug(\u001B[38;5;124m\"\u001B[39m\u001B[38;5;124mIncremented Retry for (url=\u001B[39m\u001B[38;5;124m'\u001B[39m\u001B[38;5;132;01m%s\u001B[39;00m\u001B[38;5;124m'\u001B[39m\u001B[38;5;124m): \u001B[39m\u001B[38;5;132;01m%r\u001B[39;00m\u001B[38;5;124m\"\u001B[39m, url, new_retry)\n",
      "\u001B[0;31mMaxRetryError\u001B[0m: HTTPConnectionPool(host='localhost', port=5555): Max retries exceeded with url: /ping (Caused by NewConnectionError('<urllib3.connection.HTTPConnection object at 0x1096fb340>: Failed to establish a new connection: [Errno 61] Connection refused'))",
      "\nDuring handling of the above exception, another exception occurred:\n",
      "\u001B[0;31mConnectionError\u001B[0m                           Traceback (most recent call last)",
      "Cell \u001B[0;32mIn[3], line 2\u001B[0m\n\u001B[1;32m      1\u001B[0m \u001B[38;5;28;01mimport\u001B[39;00m \u001B[38;5;21;01mrequests\u001B[39;00m\n\u001B[0;32m----> 2\u001B[0m data \u001B[38;5;241m=\u001B[39m \u001B[43mrequests\u001B[49m\u001B[38;5;241;43m.\u001B[39;49m\u001B[43mget\u001B[49m\u001B[43m(\u001B[49m\u001B[43mserver_url\u001B[49m\u001B[43m \u001B[49m\u001B[38;5;241;43m+\u001B[39;49m\u001B[43m \u001B[49m\u001B[38;5;124;43m'\u001B[39;49m\u001B[38;5;124;43m/ping\u001B[39;49m\u001B[38;5;124;43m'\u001B[39;49m\u001B[43m)\u001B[49m\n\u001B[1;32m      3\u001B[0m data\u001B[38;5;241m.\u001B[39mcontent\n",
      "File \u001B[0;32m~/Documents/Магистратура/Прикладной питон/applied_python_hw_project/.venv/lib/python3.10/site-packages/requests/api.py:73\u001B[0m, in \u001B[0;36mget\u001B[0;34m(url, params, **kwargs)\u001B[0m\n\u001B[1;32m     62\u001B[0m \u001B[38;5;28;01mdef\u001B[39;00m \u001B[38;5;21mget\u001B[39m(url, params\u001B[38;5;241m=\u001B[39m\u001B[38;5;28;01mNone\u001B[39;00m, \u001B[38;5;241m*\u001B[39m\u001B[38;5;241m*\u001B[39mkwargs):\n\u001B[1;32m     63\u001B[0m \u001B[38;5;250m    \u001B[39m\u001B[38;5;124mr\u001B[39m\u001B[38;5;124;03m\"\"\"Sends a GET request.\u001B[39;00m\n\u001B[1;32m     64\u001B[0m \n\u001B[1;32m     65\u001B[0m \u001B[38;5;124;03m    :param url: URL for the new :class:`Request` object.\u001B[39;00m\n\u001B[0;32m   (...)\u001B[0m\n\u001B[1;32m     70\u001B[0m \u001B[38;5;124;03m    :rtype: requests.Response\u001B[39;00m\n\u001B[1;32m     71\u001B[0m \u001B[38;5;124;03m    \"\"\"\u001B[39;00m\n\u001B[0;32m---> 73\u001B[0m     \u001B[38;5;28;01mreturn\u001B[39;00m \u001B[43mrequest\u001B[49m\u001B[43m(\u001B[49m\u001B[38;5;124;43m\"\u001B[39;49m\u001B[38;5;124;43mget\u001B[39;49m\u001B[38;5;124;43m\"\u001B[39;49m\u001B[43m,\u001B[49m\u001B[43m \u001B[49m\u001B[43murl\u001B[49m\u001B[43m,\u001B[49m\u001B[43m \u001B[49m\u001B[43mparams\u001B[49m\u001B[38;5;241;43m=\u001B[39;49m\u001B[43mparams\u001B[49m\u001B[43m,\u001B[49m\u001B[43m \u001B[49m\u001B[38;5;241;43m*\u001B[39;49m\u001B[38;5;241;43m*\u001B[39;49m\u001B[43mkwargs\u001B[49m\u001B[43m)\u001B[49m\n",
      "File \u001B[0;32m~/Documents/Магистратура/Прикладной питон/applied_python_hw_project/.venv/lib/python3.10/site-packages/requests/api.py:59\u001B[0m, in \u001B[0;36mrequest\u001B[0;34m(method, url, **kwargs)\u001B[0m\n\u001B[1;32m     55\u001B[0m \u001B[38;5;66;03m# By using the 'with' statement we are sure the session is closed, thus we\u001B[39;00m\n\u001B[1;32m     56\u001B[0m \u001B[38;5;66;03m# avoid leaving sockets open which can trigger a ResourceWarning in some\u001B[39;00m\n\u001B[1;32m     57\u001B[0m \u001B[38;5;66;03m# cases, and look like a memory leak in others.\u001B[39;00m\n\u001B[1;32m     58\u001B[0m \u001B[38;5;28;01mwith\u001B[39;00m sessions\u001B[38;5;241m.\u001B[39mSession() \u001B[38;5;28;01mas\u001B[39;00m session:\n\u001B[0;32m---> 59\u001B[0m     \u001B[38;5;28;01mreturn\u001B[39;00m \u001B[43msession\u001B[49m\u001B[38;5;241;43m.\u001B[39;49m\u001B[43mrequest\u001B[49m\u001B[43m(\u001B[49m\u001B[43mmethod\u001B[49m\u001B[38;5;241;43m=\u001B[39;49m\u001B[43mmethod\u001B[49m\u001B[43m,\u001B[49m\u001B[43m \u001B[49m\u001B[43murl\u001B[49m\u001B[38;5;241;43m=\u001B[39;49m\u001B[43murl\u001B[49m\u001B[43m,\u001B[49m\u001B[43m \u001B[49m\u001B[38;5;241;43m*\u001B[39;49m\u001B[38;5;241;43m*\u001B[39;49m\u001B[43mkwargs\u001B[49m\u001B[43m)\u001B[49m\n",
      "File \u001B[0;32m~/Documents/Магистратура/Прикладной питон/applied_python_hw_project/.venv/lib/python3.10/site-packages/requests/sessions.py:589\u001B[0m, in \u001B[0;36mSession.request\u001B[0;34m(self, method, url, params, data, headers, cookies, files, auth, timeout, allow_redirects, proxies, hooks, stream, verify, cert, json)\u001B[0m\n\u001B[1;32m    584\u001B[0m send_kwargs \u001B[38;5;241m=\u001B[39m {\n\u001B[1;32m    585\u001B[0m     \u001B[38;5;124m\"\u001B[39m\u001B[38;5;124mtimeout\u001B[39m\u001B[38;5;124m\"\u001B[39m: timeout,\n\u001B[1;32m    586\u001B[0m     \u001B[38;5;124m\"\u001B[39m\u001B[38;5;124mallow_redirects\u001B[39m\u001B[38;5;124m\"\u001B[39m: allow_redirects,\n\u001B[1;32m    587\u001B[0m }\n\u001B[1;32m    588\u001B[0m send_kwargs\u001B[38;5;241m.\u001B[39mupdate(settings)\n\u001B[0;32m--> 589\u001B[0m resp \u001B[38;5;241m=\u001B[39m \u001B[38;5;28;43mself\u001B[39;49m\u001B[38;5;241;43m.\u001B[39;49m\u001B[43msend\u001B[49m\u001B[43m(\u001B[49m\u001B[43mprep\u001B[49m\u001B[43m,\u001B[49m\u001B[43m \u001B[49m\u001B[38;5;241;43m*\u001B[39;49m\u001B[38;5;241;43m*\u001B[39;49m\u001B[43msend_kwargs\u001B[49m\u001B[43m)\u001B[49m\n\u001B[1;32m    591\u001B[0m \u001B[38;5;28;01mreturn\u001B[39;00m resp\n",
      "File \u001B[0;32m~/Documents/Магистратура/Прикладной питон/applied_python_hw_project/.venv/lib/python3.10/site-packages/requests/sessions.py:703\u001B[0m, in \u001B[0;36mSession.send\u001B[0;34m(self, request, **kwargs)\u001B[0m\n\u001B[1;32m    700\u001B[0m start \u001B[38;5;241m=\u001B[39m preferred_clock()\n\u001B[1;32m    702\u001B[0m \u001B[38;5;66;03m# Send the request\u001B[39;00m\n\u001B[0;32m--> 703\u001B[0m r \u001B[38;5;241m=\u001B[39m \u001B[43madapter\u001B[49m\u001B[38;5;241;43m.\u001B[39;49m\u001B[43msend\u001B[49m\u001B[43m(\u001B[49m\u001B[43mrequest\u001B[49m\u001B[43m,\u001B[49m\u001B[43m \u001B[49m\u001B[38;5;241;43m*\u001B[39;49m\u001B[38;5;241;43m*\u001B[39;49m\u001B[43mkwargs\u001B[49m\u001B[43m)\u001B[49m\n\u001B[1;32m    705\u001B[0m \u001B[38;5;66;03m# Total elapsed time of the request (approximately)\u001B[39;00m\n\u001B[1;32m    706\u001B[0m elapsed \u001B[38;5;241m=\u001B[39m preferred_clock() \u001B[38;5;241m-\u001B[39m start\n",
      "File \u001B[0;32m~/Documents/Магистратура/Прикладной питон/applied_python_hw_project/.venv/lib/python3.10/site-packages/requests/adapters.py:519\u001B[0m, in \u001B[0;36mHTTPAdapter.send\u001B[0;34m(self, request, stream, timeout, verify, cert, proxies)\u001B[0m\n\u001B[1;32m    515\u001B[0m     \u001B[38;5;28;01mif\u001B[39;00m \u001B[38;5;28misinstance\u001B[39m(e\u001B[38;5;241m.\u001B[39mreason, _SSLError):\n\u001B[1;32m    516\u001B[0m         \u001B[38;5;66;03m# This branch is for urllib3 v1.22 and later.\u001B[39;00m\n\u001B[1;32m    517\u001B[0m         \u001B[38;5;28;01mraise\u001B[39;00m SSLError(e, request\u001B[38;5;241m=\u001B[39mrequest)\n\u001B[0;32m--> 519\u001B[0m     \u001B[38;5;28;01mraise\u001B[39;00m \u001B[38;5;167;01mConnectionError\u001B[39;00m(e, request\u001B[38;5;241m=\u001B[39mrequest)\n\u001B[1;32m    521\u001B[0m \u001B[38;5;28;01mexcept\u001B[39;00m ClosedPoolError \u001B[38;5;28;01mas\u001B[39;00m e:\n\u001B[1;32m    522\u001B[0m     \u001B[38;5;28;01mraise\u001B[39;00m \u001B[38;5;167;01mConnectionError\u001B[39;00m(e, request\u001B[38;5;241m=\u001B[39mrequest)\n",
      "\u001B[0;31mConnectionError\u001B[0m: HTTPConnectionPool(host='localhost', port=5555): Max retries exceeded with url: /ping (Caused by NewConnectionError('<urllib3.connection.HTTPConnection object at 0x1096fb340>: Failed to establish a new connection: [Errno 61] Connection refused'))"
     ]
    }
   ],
   "source": [
    "import requests\n",
    "data = requests.get(server_url + '/ping')\n",
    "data.content"
   ]
  },
  {
   "cell_type": "markdown",
   "metadata": {},
   "source": [
    "# Обучаем на дефолтных данных"
   ]
  },
  {
   "cell_type": "code",
   "execution_count": null,
   "metadata": {
    "ExecuteTime": {
     "start_time": "2024-03-20T14:43:00.897407Z"
    }
   },
   "outputs": [],
   "source": [
    "data = requests.get(server_url + '/train')\n",
    "data.content"
   ]
  },
  {
   "cell_type": "markdown",
   "metadata": {},
   "source": [
    "# Обучаем на своих данных"
   ]
  },
  {
   "cell_type": "code",
   "execution_count": null,
   "metadata": {
    "ExecuteTime": {
     "end_time": "2024-03-20T14:43:00.899912Z",
     "start_time": "2024-03-20T14:43:00.899145Z"
    }
   },
   "outputs": [],
   "source": [
    "from sklearn.datasets import load_iris\n",
    "iris = load_iris()\n",
    "X, y = iris.data, iris.target\n",
    "\n",
    "data = requests.post(server_url + '/train_user',\n",
    "        json= {\n",
    "            'data': X.tolist(),\n",
    "            'target': y.tolist()\n",
    "})\n",
    "data.content"
   ]
  },
  {
   "cell_type": "markdown",
   "metadata": {},
   "source": [
    "# Предикт 1 объекта и проверяем работу кэша"
   ]
  },
  {
   "cell_type": "code",
   "execution_count": null,
   "metadata": {
    "ExecuteTime": {
     "start_time": "2024-03-20T14:43:00.900484Z"
    }
   },
   "outputs": [],
   "source": [
    "data = requests.post(server_url + '/predict',\n",
    "        json= {\n",
    "            'data': X.tolist()[0],\n",
    "})\n",
    "data.content # кэша нет"
   ]
  },
  {
   "cell_type": "code",
   "execution_count": null,
   "metadata": {
    "ExecuteTime": {
     "end_time": "2024-03-20T14:43:00.902749Z",
     "start_time": "2024-03-20T14:43:00.901827Z"
    }
   },
   "outputs": [],
   "source": [
    "data = requests.post(server_url + '/predict',\n",
    "        json= {\n",
    "            'data': X.tolist()[0],\n",
    "})\n",
    "data.content  # кэш есть"
   ]
  },
  {
   "cell_type": "markdown",
   "metadata": {},
   "source": [
    "# Предикт нескольких объектов и проверяем работу кэша"
   ]
  },
  {
   "cell_type": "code",
   "execution_count": null,
   "metadata": {
    "ExecuteTime": {
     "end_time": "2024-03-20T14:43:00.903277Z",
     "start_time": "2024-03-20T14:43:00.903210Z"
    }
   },
   "outputs": [],
   "source": [
    "data = requests.post(server_url + '/predict/multiple',\n",
    "        json= {\n",
    "            'data': X.tolist()[:2],\n",
    "})\n",
    "data.content"
   ]
  },
  {
   "cell_type": "markdown",
   "metadata": {},
   "source": [
    "# Предикт 1 объекта в методе предназнченом для нескольких объектов"
   ]
  },
  {
   "cell_type": "code",
   "execution_count": null,
   "metadata": {
    "ExecuteTime": {
     "start_time": "2024-03-20T14:43:00.903976Z"
    }
   },
   "outputs": [],
   "source": [
    "data = requests.post(server_url + '/predict/multiple',\n",
    "        json= {\n",
    "            'data': X.tolist()[0],\n",
    "})\n",
    "data.content # получаем Wrong data format"
   ]
  },
  {
   "cell_type": "code",
   "outputs": [],
   "source": [
    "import redis\n",
    "\n",
    "redis_url = 'rediss://red-cnte8nvsc6pc73cb03gg:peBJvfhrCZPT24NIqTUThCwEKBbIIoQP@frankfurt-redis.render.com:6379'\n",
    "redis_client = redis.Redis.from_url(redis_url, ssl_cert_reqs=None)\n",
    "\n",
    "# Проверяем соединение, отправляя команду PING\n",
    "try:\n",
    "    response = redis_client.ping()\n",
    "    if response:\n",
    "        print(\"Соединение с Redis успешно установлено через SSL.\")\n",
    "    else:\n",
    "        print(\"Получен неожиданный ответ от Redis.\")\n",
    "except (redis.ConnectionError, redis.TimeoutError) as e:\n",
    "    print(f\"Ошибка подключения к Redis: {e}\")"
   ],
   "metadata": {
    "collapsed": false,
    "ExecuteTime": {
     "start_time": "2024-03-20T14:43:00.904758Z"
    }
   },
   "execution_count": null
  },
  {
   "cell_type": "code",
   "outputs": [],
   "source": [],
   "metadata": {
    "collapsed": false,
    "ExecuteTime": {
     "start_time": "2024-03-20T14:43:00.905569Z"
    }
   },
   "execution_count": null
  }
 ],
 "metadata": {
  "kernelspec": {
   "display_name": "adv_py",
   "language": "python",
   "name": "python3"
  },
  "language_info": {
   "codemirror_mode": {
    "name": "ipython",
    "version": 3
   },
   "file_extension": ".py",
   "mimetype": "text/x-python",
   "name": "python",
   "nbconvert_exporter": "python",
   "pygments_lexer": "ipython3",
   "version": "3.10.11"
  }
 },
 "nbformat": 4,
 "nbformat_minor": 2
}
